<?xml version="1.0" encoding="UTF-8"?>
<testng-results ignored="0" total="4" passed="1" failed="2" skipped="1">
  <reporter-output>
  </reporter-output>
  <suite started-at="2025-02-27T05:38:54 IST" name="Default suite" finished-at="2025-02-27T05:38:56 IST" duration-ms="1273">
    <groups>
    </groups>
    <test started-at="2025-02-27T05:38:54 IST" name="Default test" finished-at="2025-02-27T05:38:56 IST" duration-ms="1273">
      <class name="listerners.TestClass">
        <test-method signature="testMethod3()[pri:0, instance:listerners.TestClass@44ebcd03]" started-at="2025-02-27T05:38:54 IST" name="testMethod3" finished-at="2025-02-27T05:38:55 IST" duration-ms="45" status="FAIL">
          <exception class="java.lang.AssertionError">
            <message>
              <![CDATA[expected [TestNGListenersDemo] but found [TestNGListeners]]]>
            </message>
            <full-stacktrace>
              <![CDATA[java.lang.AssertionError: expected [TestNGListenersDemo] but found [TestNGListeners]
at org.testng.Assert.fail(Assert.java:111)
at org.testng.Assert.failNotEquals(Assert.java:1578)
at org.testng.Assert.assertEqualsImpl(Assert.java:150)
at org.testng.Assert.assertEquals(Assert.java:132)
at org.testng.Assert.assertEquals(Assert.java:656)
at org.testng.Assert.assertEquals(Assert.java:666)
at listerners.TestClass.testMethod3(TestClass.java:25)
at java.base/jdk.internal.reflect.DirectMethodHandleAccessor.invoke(DirectMethodHandleAccessor.java:103)
at java.base/java.lang.reflect.Method.invoke(Method.java:580)
at org.testng.internal.invokers.MethodInvocationHelper.invokeMethod(MethodInvocationHelper.java:141)
at org.testng.internal.invokers.TestInvoker.invokeMethod(TestInvoker.java:686)
at org.testng.internal.invokers.TestInvoker.invokeTestMethod(TestInvoker.java:230)
at org.testng.internal.invokers.MethodRunner.runInSequence(MethodRunner.java:63)
at org.testng.internal.invokers.TestInvoker$MethodInvocationAgent.invoke(TestInvoker.java:992)
at org.testng.internal.invokers.TestInvoker.invokeTestMethods(TestInvoker.java:203)
at org.testng.internal.invokers.TestMethodWorker.invokeTestMethods(TestMethodWorker.java:154)
at org.testng.internal.invokers.TestMethodWorker.run(TestMethodWorker.java:134)
at java.base/java.util.ArrayList.forEach(ArrayList.java:1596)
at org.testng.TestRunner.privateRun(TestRunner.java:739)
at org.testng.TestRunner.run(TestRunner.java:614)
at org.testng.SuiteRunner.runTest(SuiteRunner.java:421)
at org.testng.SuiteRunner.runSequentially(SuiteRunner.java:413)
at org.testng.SuiteRunner.privateRun(SuiteRunner.java:373)
at org.testng.SuiteRunner.run(SuiteRunner.java:312)
at org.testng.SuiteRunnerWorker.runSuite(SuiteRunnerWorker.java:52)
at org.testng.SuiteRunnerWorker.run(SuiteRunnerWorker.java:95)
at org.testng.TestNG.runSuitesSequentially(TestNG.java:1274)
at org.testng.TestNG.runSuitesLocally(TestNG.java:1208)
at org.testng.TestNG.runSuites(TestNG.java:1112)
at org.testng.TestNG.run(TestNG.java:1079)
at org.testng.remote.AbstractRemoteTestNG.run(AbstractRemoteTestNG.java:115)
at org.testng.remote.RemoteTestNG.initAndRun(RemoteTestNG.java:293)
at org.testng.remote.RemoteTestNG.main(RemoteTestNG.java:91)
]]>
            </full-stacktrace>
          </exception> <!-- java.lang.AssertionError -->
          <reporter-output>
          </reporter-output>
        </test-method> <!-- testMethod3 -->
        <test-method signature="testMethod1()[pri:0, instance:listerners.TestClass@44ebcd03]" started-at="2025-02-27T05:38:55 IST" name="testMethod1" finished-at="2025-02-27T05:38:55 IST" duration-ms="7" status="PASS">
          <reporter-output>
          </reporter-output>
        </test-method> <!-- testMethod1 -->
        <test-method signature="testMethod2()[pri:0, instance:listerners.TestClass@44ebcd03]" started-at="2025-02-27T05:38:55 IST" name="testMethod2" finished-at="2025-02-27T05:38:56 IST" duration-ms="1036" status="FAIL">
          <exception class="org.testng.internal.thread.ThreadTimeoutException">
            <message>
              <![CDATA[Method listerners.TestClass.testMethod2() didn't finish within the time-out 1000]]>
            </message>
            <full-stacktrace>
              <![CDATA[org.testng.internal.thread.ThreadTimeoutException: Method listerners.TestClass.testMethod2() didn't finish within the time-out 1000
at java.base/java.lang.Thread.sleep0(Native Method)
at java.base/java.lang.Thread.sleep(Thread.java:509)
at listerners.TestClass.testMethod2(TestClass.java:18)
at java.base/jdk.internal.reflect.DirectMethodHandleAccessor.invoke(DirectMethodHandleAccessor.java:103)
at java.base/java.lang.reflect.Method.invoke(Method.java:580)
at org.testng.internal.invokers.MethodInvocationHelper.invokeMethod(MethodInvocationHelper.java:141)
at org.testng.internal.invokers.InvokeMethodRunnable.runOne(InvokeMethodRunnable.java:47)
at org.testng.internal.invokers.InvokeMethodRunnable.call(InvokeMethodRunnable.java:76)
at org.testng.internal.invokers.InvokeMethodRunnable.call(InvokeMethodRunnable.java:11)
at java.base/java.util.concurrent.FutureTask.run(FutureTask.java:317)
at java.base/java.util.concurrent.ThreadPoolExecutor.runWorker(ThreadPoolExecutor.java:1144)
at java.base/java.util.concurrent.ThreadPoolExecutor$Worker.run(ThreadPoolExecutor.java:642)
at java.base/java.lang.Thread.run(Thread.java:1583)
]]>
            </full-stacktrace>
          </exception> <!-- org.testng.internal.thread.ThreadTimeoutException -->
          <reporter-output>
          </reporter-output>
        </test-method> <!-- testMethod2 -->
        <test-method signature="testMethod4()[pri:0, instance:listerners.TestClass@44ebcd03]" started-at="2025-02-27T05:38:56 IST" name="testMethod4" finished-at="2025-02-27T05:38:56 IST" depends-on-methods="listerners.TestClass.testMethod3" duration-ms="0" status="SKIP">
          <exception class="java.lang.Throwable">
            <message>
              <![CDATA[Method listerners.TestClass.testMethod4() on instance listerners.TestClass@44ebcd03 depends on not successfully finished methods 
[listerners.TestClass.testMethod3() on instance listerners.TestClass@44ebcd03]]]>
            </message>
            <full-stacktrace>
              <![CDATA[java.lang.Throwable: Method listerners.TestClass.testMethod4() on instance listerners.TestClass@44ebcd03 depends on not successfully finished methods 
[listerners.TestClass.testMethod3() on instance listerners.TestClass@44ebcd03]
at org.testng.internal.invokers.TestInvoker.invokeTestMethods(TestInvoker.java:159)
at org.testng.internal.invokers.TestMethodWorker.invokeTestMethods(TestMethodWorker.java:154)
at org.testng.internal.invokers.TestMethodWorker.run(TestMethodWorker.java:134)
at java.base/java.util.ArrayList.forEach(ArrayList.java:1596)
at org.testng.TestRunner.privateRun(TestRunner.java:739)
at org.testng.TestRunner.run(TestRunner.java:614)
at org.testng.SuiteRunner.runTest(SuiteRunner.java:421)
at org.testng.SuiteRunner.runSequentially(SuiteRunner.java:413)
at org.testng.SuiteRunner.privateRun(SuiteRunner.java:373)
at org.testng.SuiteRunner.run(SuiteRunner.java:312)
at org.testng.SuiteRunnerWorker.runSuite(SuiteRunnerWorker.java:52)
at org.testng.SuiteRunnerWorker.run(SuiteRunnerWorker.java:95)
at org.testng.TestNG.runSuitesSequentially(TestNG.java:1274)
at org.testng.TestNG.runSuitesLocally(TestNG.java:1208)
at org.testng.TestNG.runSuites(TestNG.java:1112)
at org.testng.TestNG.run(TestNG.java:1079)
at org.testng.remote.AbstractRemoteTestNG.run(AbstractRemoteTestNG.java:115)
at org.testng.remote.RemoteTestNG.initAndRun(RemoteTestNG.java:293)
at org.testng.remote.RemoteTestNG.main(RemoteTestNG.java:91)
]]>
            </full-stacktrace>
          </exception> <!-- java.lang.Throwable -->
          <reporter-output>
          </reporter-output>
        </test-method> <!-- testMethod4 -->
      </class> <!-- listerners.TestClass -->
    </test> <!-- Default test -->
  </suite> <!-- Default suite -->
</testng-results>
