<?xml version="1.0" encoding="UTF-8"?>
<!-- Generated by org.testng.reporters.JUnitReportReporter -->
<testsuite hostname="DESKTOP-P4JKDR6" failures="0" tests="1" name="attributes_Part3.ExpectedExceptionsExample" time="0.010" errors="1" timestamp="2025-01-25T01:11:47 IST" skipped="0">
  <testcase classname="attributes_Part3.ExpectedExceptionsExample" name="testMethod" time="0.010">
    <error message="
Method ExpectedExceptionsExample.testMethod()[pri:0, instance:attributes_Part3.ExpectedExceptionsExample@6aba2b86] should have thrown an exception of any of types [class java.lang.NullPointerException, class org.testng.TestNGException]" type="org.testng.TestException">
      <![CDATA[org.testng.TestException: 
Method ExpectedExceptionsExample.testMethod()[pri:0, instance:attributes_Part3.ExpectedExceptionsExample@6aba2b86] should have thrown an exception of any of types [class java.lang.NullPointerException, class org.testng.TestNGException]
at org.testng.internal.invokers.ExpectedExceptionsHolder.noException(ExpectedExceptionsHolder.java:81)
at org.testng.internal.invokers.TestInvoker.considerExceptionsInternal(TestInvoker.java:895)
at org.testng.internal.invokers.TestInvoker.considerExceptions(TestInvoker.java:860)
at org.testng.internal.invokers.TestInvoker.invokeMethod(TestInvoker.java:741)
at org.testng.internal.invokers.TestInvoker.invokeTestMethod(TestInvoker.java:230)
at org.testng.internal.invokers.MethodRunner.runInSequence(MethodRunner.java:63)
at org.testng.internal.invokers.TestInvoker$MethodInvocationAgent.invoke(TestInvoker.java:992)
at org.testng.internal.invokers.TestInvoker.invokeTestMethods(TestInvoker.java:203)
at org.testng.internal.invokers.TestMethodWorker.invokeTestMethods(TestMethodWorker.java:154)
at org.testng.internal.invokers.TestMethodWorker.run(TestMethodWorker.java:134)
at java.base/java.util.ArrayList.forEach(ArrayList.java:1596)
at org.testng.TestRunner.privateRun(TestRunner.java:739)
at org.testng.TestRunner.run(TestRunner.java:614)
at org.testng.SuiteRunner.runTest(SuiteRunner.java:421)
at org.testng.SuiteRunner.runSequentially(SuiteRunner.java:413)
at org.testng.SuiteRunner.privateRun(SuiteRunner.java:373)
at org.testng.SuiteRunner.run(SuiteRunner.java:312)
at org.testng.SuiteRunnerWorker.runSuite(SuiteRunnerWorker.java:52)
at org.testng.SuiteRunnerWorker.run(SuiteRunnerWorker.java:95)
at org.testng.TestNG.runSuitesSequentially(TestNG.java:1274)
at org.testng.TestNG.runSuitesLocally(TestNG.java:1208)
at org.testng.TestNG.runSuites(TestNG.java:1112)
at org.testng.TestNG.run(TestNG.java:1079)
at org.testng.remote.AbstractRemoteTestNG.run(AbstractRemoteTestNG.java:115)
at org.testng.remote.RemoteTestNG.initAndRun(RemoteTestNG.java:293)
at org.testng.remote.RemoteTestNG.main(RemoteTestNG.java:91)
]]>
    </error>
  </testcase> <!-- testMethod -->
</testsuite> <!-- attributes_Part3.ExpectedExceptionsExample -->
